2018-04-05 17:06:26,482 - instagram_scraper.app - DEBUG - Exception in worker thread
Traceback (most recent call last):
  File "c:\users\juilee rege\anaconda3\lib\site-packages\instagram_scraper\app.py", line 368, in worker_wrapper
    return fn(*args, **kwargs)
  File "c:\users\juilee rege\anaconda3\lib\site-packages\instagram_scraper\app.py", line 896, in download
    os.rename(part_file, file_path)
PermissionError: [WinError 32] The process cannot access the file because it is being used by another process: './icgt\\29094526_152919962069881_8691686408806465536_n.jpg.part' -> './icgt\\29094526_152919962069881_8691686408806465536_n.jpg'
2018-04-05 17:06:26,483 - instagram_scraper.app - WARNING - Media for icgt at ['https://scontent-atl3-1.cdninstagram.com/vp/63d38fde75af7d0107fea2489a1680ea/5B6EC6B6/t51.2885-15/e35/29400835_211602239597476_5076024935776780288_n.jpg', 'https://scontent-atl3-1.cdninstagram.com/vp/652805d3a38e6b54f9ac7d394869f7e8/5B56E49B/t51.2885-15/e35/29090589_1650604114986231_2892611906365816832_n.jpg', 'https://scontent-atl3-1.cdninstagram.com/vp/6af71a7d77120214c4bdfeebcadef996/5B72F926/t51.2885-15/e35/29093767_2041190759495377_2895913679654486016_n.jpg', 'https://scontent-atl3-1.cdninstagram.com/vp/1f675f783a8b0e894cdff6b703a9550f/5B58D8E2/t51.2885-15/e35/29094526_152919962069881_8691686408806465536_n.jpg'] generated an exception: [WinError 32] The process cannot access the file because it is being used by another process: './icgt\\29094526_152919962069881_8691686408806465536_n.jpg.part' -> './icgt\\29094526_152919962069881_8691686408806465536_n.jpg'
